[2022-01-26 20:58:38,067] {taskinstance.py:1032} INFO - Dependencies all met for <TaskInstance: data_ingestion_gcs_dag.local_to_gcs_task scheduled__2022-01-25T00:00:00+00:00 [queued]>
[2022-01-26 20:58:38,080] {taskinstance.py:1032} INFO - Dependencies all met for <TaskInstance: data_ingestion_gcs_dag.local_to_gcs_task scheduled__2022-01-25T00:00:00+00:00 [queued]>
[2022-01-26 20:58:38,081] {taskinstance.py:1238} INFO - 
--------------------------------------------------------------------------------
[2022-01-26 20:58:38,081] {taskinstance.py:1239} INFO - Starting attempt 1 of 2
[2022-01-26 20:58:38,081] {taskinstance.py:1240} INFO - 
--------------------------------------------------------------------------------
[2022-01-26 20:58:38,096] {taskinstance.py:1259} INFO - Executing <Task(PythonOperator): local_to_gcs_task> on 2022-01-25 00:00:00+00:00
[2022-01-26 20:58:38,101] {standard_task_runner.py:52} INFO - Started process 193 to run task
[2022-01-26 20:58:38,104] {standard_task_runner.py:76} INFO - Running: ['***', 'tasks', 'run', 'data_ingestion_gcs_dag', 'local_to_gcs_task', 'scheduled__2022-01-25T00:00:00+00:00', '--job-id', '5', '--raw', '--subdir', 'DAGS_FOLDER/data_ingestion_gcs_dag.py', '--cfg-path', '/tmp/tmp7olqh6ll', '--error-file', '/tmp/tmproy3ssut']
[2022-01-26 20:58:38,105] {standard_task_runner.py:77} INFO - Job 5: Subtask local_to_gcs_task
[2022-01-26 20:58:38,151] {logging_mixin.py:109} INFO - Running <TaskInstance: data_ingestion_gcs_dag.local_to_gcs_task scheduled__2022-01-25T00:00:00+00:00 [running]> on host 09b8c78ea44a
[2022-01-26 20:58:38,199] {taskinstance.py:1426} INFO - Exporting the following env vars:
AIRFLOW_CTX_DAG_OWNER=***
AIRFLOW_CTX_DAG_ID=data_ingestion_gcs_dag
AIRFLOW_CTX_TASK_ID=local_to_gcs_task
AIRFLOW_CTX_EXECUTION_DATE=2022-01-25T00:00:00+00:00
AIRFLOW_CTX_DAG_RUN_ID=scheduled__2022-01-25T00:00:00+00:00
[2022-01-26 20:58:38,200] {taskinstance.py:1700} ERROR - Task failed with exception
Traceback (most recent call last):
  File "/home/airflow/.local/lib/python3.7/site-packages/airflow/models/taskinstance.py", line 1329, in _run_raw_task
    self._execute_task_with_callbacks(context)
  File "/home/airflow/.local/lib/python3.7/site-packages/airflow/models/taskinstance.py", line 1455, in _execute_task_with_callbacks
    result = self._execute_task(context, self.task)
  File "/home/airflow/.local/lib/python3.7/site-packages/airflow/models/taskinstance.py", line 1511, in _execute_task
    result = execute_callable(context=context)
  File "/home/airflow/.local/lib/python3.7/site-packages/airflow/operators/python.py", line 174, in execute
    return_value = self.execute_callable()
  File "/home/airflow/.local/lib/python3.7/site-packages/airflow/operators/python.py", line 185, in execute_callable
    return self.python_callable(*self.op_args, **self.op_kwargs)
  File "/opt/airflow/dags/data_ingestion_gcs_dag.py", line 54, in upload_to_gcs
    client = storage.Client()
  File "/home/airflow/.local/lib/python3.7/site-packages/google/cloud/storage/client.py", line 128, in __init__
    _http=_http,
  File "/home/airflow/.local/lib/python3.7/site-packages/google/cloud/client.py", line 318, in __init__
    _ClientProjectMixin.__init__(self, project=project, credentials=credentials)
  File "/home/airflow/.local/lib/python3.7/site-packages/google/cloud/client.py", line 266, in __init__
    project = self._determine_default(project)
  File "/home/airflow/.local/lib/python3.7/site-packages/google/cloud/client.py", line 285, in _determine_default
    return _determine_default_project(project)
  File "/home/airflow/.local/lib/python3.7/site-packages/google/cloud/_helpers.py", line 186, in _determine_default_project
    _, project = google.auth.default()
  File "/home/airflow/.local/lib/python3.7/site-packages/google/auth/_default.py", line 459, in default
    credentials, project_id = checker()
  File "/home/airflow/.local/lib/python3.7/site-packages/google/auth/_default.py", line 222, in _get_explicit_environ_credentials
    os.environ[environment_vars.CREDENTIALS]
  File "/home/airflow/.local/lib/python3.7/site-packages/google/auth/_default.py", line 108, in load_credentials_from_file
    "File {} was not found.".format(filename)
google.auth.exceptions.DefaultCredentialsError: File /.google/credentials/google_credentials.json was not found.
[2022-01-26 20:58:38,216] {taskinstance.py:1277} INFO - Marking task as UP_FOR_RETRY. dag_id=data_ingestion_gcs_dag, task_id=local_to_gcs_task, execution_date=20220125T000000, start_date=20220126T205838, end_date=20220126T205838
[2022-01-26 20:58:38,228] {standard_task_runner.py:92} ERROR - Failed to execute job 5 for task local_to_gcs_task
Traceback (most recent call last):
  File "/home/airflow/.local/lib/python3.7/site-packages/airflow/task/task_runner/standard_task_runner.py", line 85, in _start_by_fork
    args.func(args, dag=self.dag)
  File "/home/airflow/.local/lib/python3.7/site-packages/airflow/cli/cli_parser.py", line 48, in command
    return func(*args, **kwargs)
  File "/home/airflow/.local/lib/python3.7/site-packages/airflow/utils/cli.py", line 92, in wrapper
    return f(*args, **kwargs)
  File "/home/airflow/.local/lib/python3.7/site-packages/airflow/cli/commands/task_command.py", line 298, in task_run
    _run_task_by_selected_method(args, dag, ti)
  File "/home/airflow/.local/lib/python3.7/site-packages/airflow/cli/commands/task_command.py", line 107, in _run_task_by_selected_method
    _run_raw_task(args, ti)
  File "/home/airflow/.local/lib/python3.7/site-packages/airflow/cli/commands/task_command.py", line 184, in _run_raw_task
    error_file=args.error_file,
  File "/home/airflow/.local/lib/python3.7/site-packages/airflow/utils/session.py", line 70, in wrapper
    return func(*args, session=session, **kwargs)
  File "/home/airflow/.local/lib/python3.7/site-packages/airflow/models/taskinstance.py", line 1329, in _run_raw_task
    self._execute_task_with_callbacks(context)
  File "/home/airflow/.local/lib/python3.7/site-packages/airflow/models/taskinstance.py", line 1455, in _execute_task_with_callbacks
    result = self._execute_task(context, self.task)
  File "/home/airflow/.local/lib/python3.7/site-packages/airflow/models/taskinstance.py", line 1511, in _execute_task
    result = execute_callable(context=context)
  File "/home/airflow/.local/lib/python3.7/site-packages/airflow/operators/python.py", line 174, in execute
    return_value = self.execute_callable()
  File "/home/airflow/.local/lib/python3.7/site-packages/airflow/operators/python.py", line 185, in execute_callable
    return self.python_callable(*self.op_args, **self.op_kwargs)
  File "/opt/airflow/dags/data_ingestion_gcs_dag.py", line 54, in upload_to_gcs
    client = storage.Client()
  File "/home/airflow/.local/lib/python3.7/site-packages/google/cloud/storage/client.py", line 128, in __init__
    _http=_http,
  File "/home/airflow/.local/lib/python3.7/site-packages/google/cloud/client.py", line 318, in __init__
    _ClientProjectMixin.__init__(self, project=project, credentials=credentials)
  File "/home/airflow/.local/lib/python3.7/site-packages/google/cloud/client.py", line 266, in __init__
    project = self._determine_default(project)
  File "/home/airflow/.local/lib/python3.7/site-packages/google/cloud/client.py", line 285, in _determine_default
    return _determine_default_project(project)
  File "/home/airflow/.local/lib/python3.7/site-packages/google/cloud/_helpers.py", line 186, in _determine_default_project
    _, project = google.auth.default()
  File "/home/airflow/.local/lib/python3.7/site-packages/google/auth/_default.py", line 459, in default
    credentials, project_id = checker()
  File "/home/airflow/.local/lib/python3.7/site-packages/google/auth/_default.py", line 222, in _get_explicit_environ_credentials
    os.environ[environment_vars.CREDENTIALS]
  File "/home/airflow/.local/lib/python3.7/site-packages/google/auth/_default.py", line 108, in load_credentials_from_file
    "File {} was not found.".format(filename)
google.auth.exceptions.DefaultCredentialsError: File /.google/credentials/google_credentials.json was not found.
[2022-01-26 20:58:38,236] {local_task_job.py:154} INFO - Task exited with return code 1
[2022-01-26 20:58:38,272] {local_task_job.py:264} INFO - 0 downstream tasks scheduled from follow-on schedule check
[2022-01-26 22:27:36,885] {taskinstance.py:1032} INFO - Dependencies all met for <TaskInstance: data_ingestion_gcs_dag.local_to_gcs_task scheduled__2022-01-25T00:00:00+00:00 [queued]>
[2022-01-26 22:27:36,894] {taskinstance.py:1032} INFO - Dependencies all met for <TaskInstance: data_ingestion_gcs_dag.local_to_gcs_task scheduled__2022-01-25T00:00:00+00:00 [queued]>
[2022-01-26 22:27:36,895] {taskinstance.py:1238} INFO - 
--------------------------------------------------------------------------------
[2022-01-26 22:27:36,895] {taskinstance.py:1239} INFO - Starting attempt 1 of 2
[2022-01-26 22:27:36,896] {taskinstance.py:1240} INFO - 
--------------------------------------------------------------------------------
[2022-01-26 22:27:36,906] {taskinstance.py:1259} INFO - Executing <Task(PythonOperator): local_to_gcs_task> on 2022-01-25 00:00:00+00:00
[2022-01-26 22:27:36,911] {standard_task_runner.py:52} INFO - Started process 165 to run task
[2022-01-26 22:27:36,914] {standard_task_runner.py:76} INFO - Running: ['***', 'tasks', 'run', 'data_ingestion_gcs_dag', 'local_to_gcs_task', 'scheduled__2022-01-25T00:00:00+00:00', '--job-id', '5', '--raw', '--subdir', 'DAGS_FOLDER/data_ingestion_gcs_dag.py', '--cfg-path', '/tmp/tmpck3ufk8j', '--error-file', '/tmp/tmpjpfp85ji']
[2022-01-26 22:27:36,915] {standard_task_runner.py:77} INFO - Job 5: Subtask local_to_gcs_task
[2022-01-26 22:27:36,961] {logging_mixin.py:109} INFO - Running <TaskInstance: data_ingestion_gcs_dag.local_to_gcs_task scheduled__2022-01-25T00:00:00+00:00 [running]> on host 062265fab11f
[2022-01-26 22:27:37,009] {taskinstance.py:1426} INFO - Exporting the following env vars:
AIRFLOW_CTX_DAG_OWNER=***
AIRFLOW_CTX_DAG_ID=data_ingestion_gcs_dag
AIRFLOW_CTX_TASK_ID=local_to_gcs_task
AIRFLOW_CTX_EXECUTION_DATE=2022-01-25T00:00:00+00:00
AIRFLOW_CTX_DAG_RUN_ID=scheduled__2022-01-25T00:00:00+00:00
[2022-01-26 22:27:37,011] {taskinstance.py:1700} ERROR - Task failed with exception
Traceback (most recent call last):
  File "/home/airflow/.local/lib/python3.7/site-packages/airflow/models/taskinstance.py", line 1329, in _run_raw_task
    self._execute_task_with_callbacks(context)
  File "/home/airflow/.local/lib/python3.7/site-packages/airflow/models/taskinstance.py", line 1455, in _execute_task_with_callbacks
    result = self._execute_task(context, self.task)
  File "/home/airflow/.local/lib/python3.7/site-packages/airflow/models/taskinstance.py", line 1511, in _execute_task
    result = execute_callable(context=context)
  File "/home/airflow/.local/lib/python3.7/site-packages/airflow/operators/python.py", line 174, in execute
    return_value = self.execute_callable()
  File "/home/airflow/.local/lib/python3.7/site-packages/airflow/operators/python.py", line 185, in execute_callable
    return self.python_callable(*self.op_args, **self.op_kwargs)
  File "/opt/airflow/dags/data_ingestion_gcs_dag.py", line 54, in upload_to_gcs
    client = storage.Client()
  File "/home/airflow/.local/lib/python3.7/site-packages/google/cloud/storage/client.py", line 128, in __init__
    _http=_http,
  File "/home/airflow/.local/lib/python3.7/site-packages/google/cloud/client.py", line 318, in __init__
    _ClientProjectMixin.__init__(self, project=project, credentials=credentials)
  File "/home/airflow/.local/lib/python3.7/site-packages/google/cloud/client.py", line 266, in __init__
    project = self._determine_default(project)
  File "/home/airflow/.local/lib/python3.7/site-packages/google/cloud/client.py", line 285, in _determine_default
    return _determine_default_project(project)
  File "/home/airflow/.local/lib/python3.7/site-packages/google/cloud/_helpers.py", line 186, in _determine_default_project
    _, project = google.auth.default()
  File "/home/airflow/.local/lib/python3.7/site-packages/google/auth/_default.py", line 459, in default
    credentials, project_id = checker()
  File "/home/airflow/.local/lib/python3.7/site-packages/google/auth/_default.py", line 222, in _get_explicit_environ_credentials
    os.environ[environment_vars.CREDENTIALS]
  File "/home/airflow/.local/lib/python3.7/site-packages/google/auth/_default.py", line 108, in load_credentials_from_file
    "File {} was not found.".format(filename)
google.auth.exceptions.DefaultCredentialsError: File /.google/credentials/google_credentials.json was not found.
[2022-01-26 22:27:37,031] {taskinstance.py:1277} INFO - Marking task as UP_FOR_RETRY. dag_id=data_ingestion_gcs_dag, task_id=local_to_gcs_task, execution_date=20220125T000000, start_date=20220126T222736, end_date=20220126T222737
[2022-01-26 22:27:37,044] {standard_task_runner.py:92} ERROR - Failed to execute job 5 for task local_to_gcs_task
Traceback (most recent call last):
  File "/home/airflow/.local/lib/python3.7/site-packages/airflow/task/task_runner/standard_task_runner.py", line 85, in _start_by_fork
    args.func(args, dag=self.dag)
  File "/home/airflow/.local/lib/python3.7/site-packages/airflow/cli/cli_parser.py", line 48, in command
    return func(*args, **kwargs)
  File "/home/airflow/.local/lib/python3.7/site-packages/airflow/utils/cli.py", line 92, in wrapper
    return f(*args, **kwargs)
  File "/home/airflow/.local/lib/python3.7/site-packages/airflow/cli/commands/task_command.py", line 298, in task_run
    _run_task_by_selected_method(args, dag, ti)
  File "/home/airflow/.local/lib/python3.7/site-packages/airflow/cli/commands/task_command.py", line 107, in _run_task_by_selected_method
    _run_raw_task(args, ti)
  File "/home/airflow/.local/lib/python3.7/site-packages/airflow/cli/commands/task_command.py", line 184, in _run_raw_task
    error_file=args.error_file,
  File "/home/airflow/.local/lib/python3.7/site-packages/airflow/utils/session.py", line 70, in wrapper
    return func(*args, session=session, **kwargs)
  File "/home/airflow/.local/lib/python3.7/site-packages/airflow/models/taskinstance.py", line 1329, in _run_raw_task
    self._execute_task_with_callbacks(context)
  File "/home/airflow/.local/lib/python3.7/site-packages/airflow/models/taskinstance.py", line 1455, in _execute_task_with_callbacks
    result = self._execute_task(context, self.task)
  File "/home/airflow/.local/lib/python3.7/site-packages/airflow/models/taskinstance.py", line 1511, in _execute_task
    result = execute_callable(context=context)
  File "/home/airflow/.local/lib/python3.7/site-packages/airflow/operators/python.py", line 174, in execute
    return_value = self.execute_callable()
  File "/home/airflow/.local/lib/python3.7/site-packages/airflow/operators/python.py", line 185, in execute_callable
    return self.python_callable(*self.op_args, **self.op_kwargs)
  File "/opt/airflow/dags/data_ingestion_gcs_dag.py", line 54, in upload_to_gcs
    client = storage.Client()
  File "/home/airflow/.local/lib/python3.7/site-packages/google/cloud/storage/client.py", line 128, in __init__
    _http=_http,
  File "/home/airflow/.local/lib/python3.7/site-packages/google/cloud/client.py", line 318, in __init__
    _ClientProjectMixin.__init__(self, project=project, credentials=credentials)
  File "/home/airflow/.local/lib/python3.7/site-packages/google/cloud/client.py", line 266, in __init__
    project = self._determine_default(project)
  File "/home/airflow/.local/lib/python3.7/site-packages/google/cloud/client.py", line 285, in _determine_default
    return _determine_default_project(project)
  File "/home/airflow/.local/lib/python3.7/site-packages/google/cloud/_helpers.py", line 186, in _determine_default_project
    _, project = google.auth.default()
  File "/home/airflow/.local/lib/python3.7/site-packages/google/auth/_default.py", line 459, in default
    credentials, project_id = checker()
  File "/home/airflow/.local/lib/python3.7/site-packages/google/auth/_default.py", line 222, in _get_explicit_environ_credentials
    os.environ[environment_vars.CREDENTIALS]
  File "/home/airflow/.local/lib/python3.7/site-packages/google/auth/_default.py", line 108, in load_credentials_from_file
    "File {} was not found.".format(filename)
google.auth.exceptions.DefaultCredentialsError: File /.google/credentials/google_credentials.json was not found.
[2022-01-26 22:27:37,086] {local_task_job.py:154} INFO - Task exited with return code 1
[2022-01-26 22:27:37,147] {local_task_job.py:264} INFO - 0 downstream tasks scheduled from follow-on schedule check
[2022-01-26 22:37:01,428] {taskinstance.py:1032} INFO - Dependencies all met for <TaskInstance: data_ingestion_gcs_dag.local_to_gcs_task scheduled__2022-01-25T00:00:00+00:00 [queued]>
[2022-01-26 22:37:01,438] {taskinstance.py:1032} INFO - Dependencies all met for <TaskInstance: data_ingestion_gcs_dag.local_to_gcs_task scheduled__2022-01-25T00:00:00+00:00 [queued]>
[2022-01-26 22:37:01,438] {taskinstance.py:1238} INFO - 
--------------------------------------------------------------------------------
[2022-01-26 22:37:01,439] {taskinstance.py:1239} INFO - Starting attempt 1 of 2
[2022-01-26 22:37:01,439] {taskinstance.py:1240} INFO - 
--------------------------------------------------------------------------------
[2022-01-26 22:37:01,450] {taskinstance.py:1259} INFO - Executing <Task(PythonOperator): local_to_gcs_task> on 2022-01-25 00:00:00+00:00
[2022-01-26 22:37:01,454] {standard_task_runner.py:52} INFO - Started process 182 to run task
[2022-01-26 22:37:01,457] {standard_task_runner.py:76} INFO - Running: ['***', 'tasks', 'run', 'data_ingestion_gcs_dag', 'local_to_gcs_task', 'scheduled__2022-01-25T00:00:00+00:00', '--job-id', '5', '--raw', '--subdir', 'DAGS_FOLDER/data_ingestion_gcs_dag.py', '--cfg-path', '/tmp/tmpzlsuhfy0', '--error-file', '/tmp/tmpmip9hqoj']
[2022-01-26 22:37:01,458] {standard_task_runner.py:77} INFO - Job 5: Subtask local_to_gcs_task
[2022-01-26 22:37:01,505] {logging_mixin.py:109} INFO - Running <TaskInstance: data_ingestion_gcs_dag.local_to_gcs_task scheduled__2022-01-25T00:00:00+00:00 [running]> on host 23953897a00d
[2022-01-26 22:37:01,553] {taskinstance.py:1426} INFO - Exporting the following env vars:
AIRFLOW_CTX_DAG_OWNER=***
AIRFLOW_CTX_DAG_ID=data_ingestion_gcs_dag
AIRFLOW_CTX_TASK_ID=local_to_gcs_task
AIRFLOW_CTX_EXECUTION_DATE=2022-01-25T00:00:00+00:00
AIRFLOW_CTX_DAG_RUN_ID=scheduled__2022-01-25T00:00:00+00:00
[2022-01-26 22:37:33,246] {python.py:175} INFO - Done. Returned value was: None
[2022-01-26 22:37:33,261] {taskinstance.py:1277} INFO - Marking task as SUCCESS. dag_id=data_ingestion_gcs_dag, task_id=local_to_gcs_task, execution_date=20220125T000000, start_date=20220126T223701, end_date=20220126T223733
[2022-01-26 22:37:33,288] {local_task_job.py:154} INFO - Task exited with return code 0
[2022-01-26 22:37:33,317] {local_task_job.py:264} INFO - 1 downstream tasks scheduled from follow-on schedule check
